<?xml version="1.0" ?>
<!-- =================================================================================== -->
<!-- |    This document was autogenerated by xacro from /home/crasun/spot_ws/src/spot_and_manipulator_ros/spot_description/urdf/spot.urdf.xacro | -->
<!-- |    EDITING THIS FILE BY HAND IS NOT RECOMMENDED                                 | -->
<!-- =================================================================================== -->
<robot name="spot">
    <!-- We do not specify links for the cameras in the URDF. Instead, transforms for those are
         published by the driver (see spot_driver package) during runtime, so that the transforms
         include calibration adjustments. -->
    <link name="body">
        <visual>
            <geometry>
                <mesh filename="package://spot_description/meshes/body/body.dae" />
            </geometry>
        </visual>
        <collision>
            <geometry>
                <mesh filename="package://spot_description/meshes/body/body_collision.stl" />
            </geometry>
        </collision>
        <inertial>
            <mass value="0.1" />
            <origin xyz="0 0 0" rpy="0 0 0" />
            <inertia ixx="0.03" iyy="0.03" izz="0.03" ixy="0.0" ixz="0.0" iyz="0.0" />
        </inertial>
    </link>
    <link name="base_link" />
    <joint name="base_link_joint" type="fixed">
        <origin rpy="0 0 0" xyz="0 0 0" />
        <parent link="body" />
        <child link="base_link" />
    </joint>
    <link name="front_rail" />
    <joint name="front_rail_joint" type="fixed">
        <origin rpy="0 0 0" xyz="0.223 0 0.0805" />
        <parent link="body" />
        <child link="front_rail" />
    </joint>
    <link name="rear_rail" />
    <joint name="rear_rail_joint" type="fixed">
        <origin rpy="0 0 0" xyz="-0.223 0 0.0805" />
        <parent link="body" />
        <child link="rear_rail" />
    </joint>
    <link name="front_left_hip">
        <visual>
            <geometry>
                <mesh filename="package://spot_description/meshes/body/front_left_hip.dae" />
            </geometry>
        </visual>
        <collision>
            <geometry>
                <mesh filename="package://spot_description/meshes/body/front_left_hip_collision.stl" />
            </geometry>
        </collision>
        <inertial>
            <mass value="0.1" />
            <origin xyz="0 0 0" rpy="0 0 0" />
            <inertia ixx="0.03" iyy="0.03" izz="0.03" ixy="0.0" ixz="0.0" iyz="0.0" />
        </inertial>
    </link>
    <joint name="front_left_hip_x" type="revolute">
        <origin rpy="0 0 0" xyz="0.29785 0.05500 0.00000" />
        <axis xyz="1 0 0" />
        <parent link="body" />
        <child link="front_left_hip" />
        <limit effort="1000" lower="-0.78539816339744827899" upper="0.78539816339744827899" velocity="1000.00" />
    </joint>
    <link name="front_left_upper_leg">
        <visual>
            <geometry>
                <mesh filename="package://spot_description/meshes/body/front_left_upper_leg.dae" />
            </geometry>
        </visual>
        <collision>
            <geometry>
                <mesh filename="package://spot_description/meshes/body/front_left_upper_leg_collision.stl" />
            </geometry>
        </collision>
        <inertial>
            <mass value="0.1" />
            <origin xyz="0 0 0" rpy="0 0 0" />
            <inertia ixx="0.03" iyy="0.03" izz="0.03" ixy="0.0" ixz="0.0" iyz="0.0" />
        </inertial>
    </link>
    <joint name="front_left_hip_y" type="revolute">
        <origin rpy="0 0 0" xyz="0.0 0.110945 0.0" />
        <axis xyz="0 1 0" />
        <parent link="front_left_hip" />
        <child link="front_left_upper_leg" />
        <limit effort="1000" lower="-0.89884456477707963539" upper="2.2951079663725435509" velocity="1000.00" />
    </joint>
    <link name="front_left_lower_leg">
        <visual>
            <geometry>
                <mesh filename="package://spot_description/meshes/body/front_left_lower_leg.dae" />
            </geometry>
        </visual>
        <collision>
            <geometry>
                <mesh filename="package://spot_description/meshes/body/front_left_lower_leg_collision.stl" />
            </geometry>
        </collision>
        <inertial>
            <mass value="0.1" />
            <origin xyz="0 0 0" rpy="0 0 0" />
            <inertia ixx="0.03" iyy="0.03" izz="0.03" ixy="0.0" ixz="0.0" iyz="0.0" />
        </inertial>
    </link>
    <joint name="front_left_knee" type="revolute">
        <origin rpy="0 0 0" xyz="0.025 0.000 -0.3205" />
        <axis xyz="0 1 0" />
        <parent link="front_left_upper_leg" />
        <child link="front_left_lower_leg" />
        <limit effort="1000" lower="-2.7929" upper="-0.254801" velocity="1000.00" />
    </joint>
    <link name="front_right_hip">
        <visual>
            <geometry>
                <mesh filename="package://spot_description/meshes/body/front_right_hip.dae" />
            </geometry>
        </visual>
        <collision>
            <geometry>
                <mesh filename="package://spot_description/meshes/body/front_right_hip_collision.stl" />
            </geometry>
        </collision>
        <inertial>
            <mass value="0.1" />
            <origin xyz="0 0 0" rpy="0 0 0" />
            <inertia ixx="0.03" iyy="0.03" izz="0.03" ixy="0.0" ixz="0.0" iyz="0.0" />
        </inertial>
    </link>
    <joint name="front_right_hip_x" type="revolute">
        <origin rpy="0 0 0" xyz="0.29785 -0.05500 0.00000" />
        <axis xyz="1 0 0" />
        <parent link="body" />
        <child link="front_right_hip" />
        <limit effort="1000" lower="-0.78539816339744827899" upper="0.78539816339744827899" velocity="1000.00" />
    </joint>
    <link name="front_right_upper_leg">
        <visual>
            <geometry>
                <mesh filename="package://spot_description/meshes/body/front_right_upper_leg.dae" />
            </geometry>
        </visual>
        <collision>
            <geometry>
                <mesh filename="package://spot_description/meshes/body/front_right_upper_leg_collision.stl" />
            </geometry>
        </collision>
        <inertial>
            <mass value="0.1" />
            <origin xyz="0 0 0" rpy="0 0 0" />
            <inertia ixx="0.03" iyy="0.03" izz="0.03" ixy="0.0" ixz="0.0" iyz="0.0" />
        </inertial>
    </link>
    <joint name="front_right_hip_y" type="revolute">
        <origin rpy="0 0 0" xyz="0.0 -0.110945 0.0" />
        <axis xyz="0 1 0" />
        <parent link="front_right_hip" />
        <child link="front_right_upper_leg" />
        <limit effort="1000" lower="-0.89884456477707963539" upper="2.2951079663725435509" velocity="1000.00" />
    </joint>
    <link name="front_right_lower_leg">
        <visual>
            <geometry>
                <mesh filename="package://spot_description/meshes/body/front_right_lower_leg.dae" />
            </geometry>
        </visual>
        <collision>
            <geometry>
                <mesh filename="package://spot_description/meshes/body/front_right_lower_leg_collision.stl" />
            </geometry>
        </collision>
        <inertial>
            <mass value="0.1" />
            <origin xyz="0 0 0" rpy="0 0 0" />
            <inertia ixx="0.03" iyy="0.03" izz="0.03" ixy="0.0" ixz="0.0" iyz="0.0" />
        </inertial>
    </link>
    <joint name="front_right_knee" type="revolute">
        <origin rpy="0 0 0" xyz="0.025 0.000 -0.3205" />
        <axis xyz="0 1 0" />
        <parent link="front_right_upper_leg" />
        <child link="front_right_lower_leg" />
        <limit effort="1000" lower="-2.7929" upper="-0.247563" velocity="1000.00" />
    </joint>
    <link name="rear_left_hip">
        <visual>
            <geometry>
                <mesh filename="package://spot_description/meshes/body/rear_left_hip.dae" />
            </geometry>
        </visual>
        <collision>
            <geometry>
                <mesh filename="package://spot_description/meshes/body/rear_left_hip_collision.stl" />
            </geometry>
        </collision>
        <inertial>
            <mass value="0.1" />
            <origin xyz="0 0 0" rpy="0 0 0" />
            <inertia ixx="0.03" iyy="0.03" izz="0.03" ixy="0.0" ixz="0.0" iyz="0.0" />
        </inertial>
    </link>
    <joint name="rear_left_hip_x" type="revolute">
        <origin rpy="0 0 0" xyz="-0.29785 0.05500 0.00000" />
        <axis xyz="1 0 0" />
        <parent link="body" />
        <child link="rear_left_hip" />
        <limit effort="1000" lower="-0.78539816339744827899" upper="0.78539816339744827899" velocity="1000.00" />
    </joint>
    <link name="rear_left_upper_leg">
        <visual>
            <geometry>
                <mesh filename="package://spot_description/meshes/body/rear_left_upper_leg.dae" />
            </geometry>
        </visual>
        <collision>
            <geometry>
                <mesh filename="package://spot_description/meshes/body/rear_left_upper_leg_collision.stl" />
            </geometry>
        </collision>
        <inertial>
            <mass value="0.1" />
            <origin xyz="0 0 0" rpy="0 0 0" />
            <inertia ixx="0.03" iyy="0.03" izz="0.03" ixy="0.0" ixz="0.0" iyz="0.0" />
        </inertial>
    </link>
    <joint name="rear_left_hip_y" type="revolute">
        <origin rpy="0 0 0" xyz="0.0 0.110945 0.0" />
        <axis xyz="0 1 0" />
        <parent link="rear_left_hip" />
        <child link="rear_left_upper_leg" />
        <limit effort="1000" lower="-0.89884456477707963539" upper="2.2951079663725435509" velocity="1000.00" />
    </joint>
    <link name="rear_left_lower_leg">
        <visual>
            <geometry>
                <mesh filename="package://spot_description/meshes/body/rear_left_lower_leg.dae" />
            </geometry>
        </visual>
        <collision>
            <geometry>
                <mesh filename="package://spot_description/meshes/body/rear_left_lower_leg_collision.stl" />
            </geometry>
        </collision>
        <inertial>
            <mass value="0.1" />
            <origin xyz="0 0 0" rpy="0 0 0" />
            <inertia ixx="0.03" iyy="0.03" izz="0.03" ixy="0.0" ixz="0.0" iyz="0.0" />
        </inertial>
    </link>
    <joint name="rear_left_knee" type="revolute">
        <origin rpy="0 0 0" xyz="0.025 0.000 -0.3205" />
        <axis xyz="0 1 0" />
        <parent link="rear_left_upper_leg" />
        <child link="rear_left_lower_leg" />
        <limit effort="1000" lower="-2.7929" upper="-0.267153" velocity="1000.00" />
    </joint>
    <link name="rear_right_hip">
        <visual>
            <geometry>
                <mesh filename="package://spot_description/meshes/body/rear_right_hip.dae" />
            </geometry>
        </visual>
        <collision>
            <geometry>
                <mesh filename="package://spot_description/meshes/body/rear_right_hip_collision.stl" />
            </geometry>
        </collision>
        <inertial>
            <mass value="0.1" />
            <origin xyz="0 0 0" rpy="0 0 0" />
            <inertia ixx="0.03" iyy="0.03" izz="0.03" ixy="0.0" ixz="0.0" iyz="0.0" />
        </inertial>
    </link>
    <joint name="rear_right_hip_x" type="revolute">
        <origin rpy="0 0 0" xyz="-0.29785 -0.05500 0.00000" />
        <axis xyz="1 0 0" />
        <parent link="body" />
        <child link="rear_right_hip" />
        <limit effort="1000" lower="-0.78539816339744827899" upper="0.78539816339744827899" velocity="1000.00" />
    </joint>
    <link name="rear_right_upper_leg">
        <visual>
            <geometry>
                <mesh filename="package://spot_description/meshes/body/rear_right_upper_leg.dae" />
            </geometry>
        </visual>
        <collision>
            <geometry>
                <mesh filename="package://spot_description/meshes/body/rear_right_upper_leg_collision.stl" />
            </geometry>
        </collision>
        <inertial>
            <mass value="0.1" />
            <origin xyz="0 0 0" rpy="0 0 0" />
            <inertia ixx="0.03" iyy="0.03" izz="0.03" ixy="0.0" ixz="0.0" iyz="0.0" />
        </inertial>
    </link>
    <joint name="rear_right_hip_y" type="revolute">
        <origin rpy="0 0 0" xyz="0.0 -0.110945 0.0" />
        <axis xyz="0 1 0" />
        <parent link="rear_right_hip" />
        <child link="rear_right_upper_leg" />
        <limit effort="1000" lower="-0.89884456477707963539" upper="2.2951079663725435509" velocity="1000.00" />
    </joint>
    <link name="rear_right_lower_leg">
        <visual>
            <geometry>
                <mesh filename="package://spot_description/meshes/body/rear_right_lower_leg.dae" />
            </geometry>
        </visual>
        <collision>
            <geometry>
                <mesh filename="package://spot_description/meshes/body/rear_right_lower_leg_collision.stl" />
            </geometry>
        </collision>
        <inertial>
            <mass value="0.1" />
            <origin xyz="0 0 0" rpy="0 0 0" />
            <inertia ixx="0.03" iyy="0.03" izz="0.03" ixy="0.0" ixz="0.0" iyz="0.0" />
        </inertial>
    </link>
    <joint name="rear_right_knee" type="revolute">
        <origin rpy="0 0 0" xyz="0.025 0.000 -0.3205" />
        <axis xyz="0 1 0" />
        <parent link="rear_right_upper_leg" />
        <child link="rear_right_lower_leg" />
        <limit effort="1000" lower="-2.7929" upper="-0.257725" velocity="1000.00" />
    </joint>
    <!-- Transmissions -->
    <transmission name="tran1">
        <type>transmission_interface/SimpleTransmission</type>
        <joint name="arm0_shoulder_yaw">
            <hardwareInterface>hardware_interface/PositionJointInterface</hardwareInterface>
        </joint>
        <actuator name="motor1">
            <hardwareInterface>hardware_interface/PositionJointInterface</hardwareInterface>
            <mechanicalReduction>1</mechanicalReduction>
        </actuator>
    </transmission>
    <transmission name="tran2">
        <type>transmission_interface/SimpleTransmission</type>
        <joint name="arm0_shoulder_pitch">
            <hardwareInterface>hardware_interface/PositionJointInterface</hardwareInterface>
        </joint>
        <actuator name="motor2">
            <hardwareInterface>hardware_interface/PositionJointInterface</hardwareInterface>
            <mechanicalReduction>1</mechanicalReduction>
        </actuator>
    </transmission>
    <transmission name="tran3">
        <type>transmission_interface/SimpleTransmission</type>
        <joint name="arm0_elbow_pitch">
            <hardwareInterface>hardware_interface/PositionJointInterface</hardwareInterface>
        </joint>
        <actuator name="motor3">
            <hardwareInterface>hardware_interface/PositionJointInterface</hardwareInterface>
            <mechanicalReduction>1</mechanicalReduction>
        </actuator>
    </transmission>
    <transmission name="tran4">
        <type>transmission_interface/SimpleTransmission</type>
        <joint name="arm0_elbow_roll">
            <hardwareInterface>hardware_interface/PositionJointInterface</hardwareInterface>
        </joint>
        <actuator name="motor4">
            <hardwareInterface>hardware_interface/PositionJointInterface</hardwareInterface>
            <mechanicalReduction>1</mechanicalReduction>
        </actuator>
    </transmission>
    <transmission name="tran5">
        <type>transmission_interface/SimpleTransmission</type>
        <joint name="arm0_wrist_pitch">
            <hardwareInterface>hardware_interface/PositionJointInterface</hardwareInterface>
        </joint>
        <actuator name="motor5">
            <hardwareInterface>hardware_interface/PositionJointInterface</hardwareInterface>
            <mechanicalReduction>1</mechanicalReduction>
        </actuator>
    </transmission>
    <transmission name="tran6">
        <type>transmission_interface/SimpleTransmission</type>
        <joint name="arm0_wrist_roll">
            <hardwareInterface>hardware_interface/PositionJointInterface</hardwareInterface>
        </joint>
        <actuator name="motor6">
            <hardwareInterface>hardware_interface/PositionJointInterface</hardwareInterface>
            <mechanicalReduction>1</mechanicalReduction>
        </actuator>
    </transmission>
    <!-- EOF Transmissions -->
    <link name="arm0_base_link" />
    <link name="arm0_shoulder_yaw">
        <visual>
            <origin rpy="0 0 0" xyz="0 0 0" />
            <geometry>
                <mesh filename="package://spot_description/meshes/arm/arm0.link_sh0.obj" />
            </geometry>
            <material name="arm0.link_sh0">
                <color rgba="0.2 0.2 0.2 1" />
            </material>
        </visual>
        <collision>
            <origin rpy="0 0 0" xyz="0 0 0" />
            <geometry>
                <mesh filename="package://spot_description/meshes/arm/arm0.link_sh0.obj" />
            </geometry>
            <material name="arm0.link_sh0">
                <color rgba="1 0.2 0.2 1" />
            </material>
        </collision>
        <inertial>
            <mass value="0.1" />
            <origin xyz="0 0 0" rpy="0 0 0" />
            <inertia ixx="0.03" iyy="0.03" izz="0.03" ixy="0.0" ixz="0.0" iyz="0.0" />
        </inertial>
    </link>
    <joint name="arm0_shoulder_yaw" type="revolute">
        <origin rpy="0 0 0" xyz="0 0 0" />
        <axis xyz="0 0 1" />
        <parent link="arm0_base_link" />
        <child link="arm0_shoulder_yaw" />
        <limit effort="1000" lower="-2.61799387799149441136" upper="3.14159265358979311599" velocity="1000.00" />
    </joint>
    <link name="arm0_shoulder_pitch">
        <visual>
            <origin rpy="0 0 0" xyz="0 0 0" />
            <geometry>
                <mesh filename="package://spot_description/meshes/arm/arm0.link_sh1.obj" />
            </geometry>
            <material name="arm0.link_sh1">
                <color rgba="0.2 0.2 0.2 1" />
            </material>
        </visual>
        <collision>
            <origin rpy="0 0 0" xyz="0 0 0" />
            <geometry>
                <mesh filename="package://spot_description/meshes/arm/arm0.link_sh1.obj" />
            </geometry>
            <material name="arm0.link_sh1">
                <color rgba="1 0.2 0.2 1" />
            </material>
        </collision>
        <inertial>
            <mass value="0.1" />
            <origin xyz="0 0 0" rpy="0 0 0" />
            <inertia ixx="0.03" iyy="0.03" izz="0.03" ixy="0.0" ixz="0.0" iyz="0.0" />
        </inertial>
    </link>
    <joint name="arm0_shoulder_pitch" type="revolute">
        <origin rpy="0 0 0" xyz="0.0 0.0 0.0" />
        <axis xyz="0 1 0" />
        <parent link="arm0_shoulder_yaw" />
        <child link="arm0_shoulder_pitch" />
        <limit effort="1000" lower="-3.14159265358979311599" upper="0.52359877559829881565" velocity="1000.00" />
    </joint>
    <link name="arm0_shoulder_roll">
        <visual>
            <origin rpy="0 0 0" xyz="0 0 0" />
            <geometry>
                <mesh filename="package://spot_description/meshes/arm/arm0.link_hr0.obj" />
            </geometry>
            <material name="arm0.link_hr0">
                <color rgba="0.2 0.2 0.2 1" />
            </material>
        </visual>
        <collision>
            <origin rpy="0 0 0" xyz="0 0 0" />
            <geometry>
                <mesh filename="package://spot_description/meshes/arm/arm0.link_hr0.obj" />
            </geometry>
            <material name="arm0.link_hr0">
                <color rgba="1 0.2 0.2 1" />
            </material>
        </collision>
        <inertial>
            <mass value="0.1" />
            <origin xyz="0 0 0" rpy="0 0 0" />
            <inertia ixx="0.03" iyy="0.03" izz="0.03" ixy="0.0" ixz="0.0" iyz="0.0" />
        </inertial>
    </link>
    <joint name="arm0_shoulder_roll" type="fixed">
        <origin rpy="0 0 0" xyz="0.0 0.0 0.0" />
        <axis xyz="1 0 0" />
        <parent link="arm0_shoulder_pitch" />
        <child link="arm0_shoulder_roll" />
        <limit effort="0" lower="0" upper="0" velocity="0" />
    </joint>
    <link name="arm0_elbow_pitch">
        <visual>
            <origin rpy="0 0 0" xyz="0 0 0" />
            <geometry>
                <mesh filename="package://spot_description/meshes/arm/arm0.link_el0.obj" />
            </geometry>
            <material name="arm0.link_el0">
                <color rgba="0.2 0.2 0.2 1" />
            </material>
        </visual>
        <collision>
            <origin rpy="0 0 0" xyz="0 0 0" />
            <geometry>
                <mesh filename="package://spot_description/meshes/arm/arm0.link_el0.obj" />
            </geometry>
            <material name="arm0.link_el0">
                <color rgba="1 0.2 0.2 1" />
            </material>
        </collision>
        <inertial>
            <mass value="0.1" />
            <origin xyz="0 0 0" rpy="0 0 0" />
            <inertia ixx="0.03" iyy="0.03" izz="0.03" ixy="0.0" ixz="0.0" iyz="0.0" />
        </inertial>
    </link>
    <joint name="arm0_elbow_pitch" type="revolute">
        <origin rpy="0 0 0" xyz="0.3385 0 0" />
        <axis xyz="0 1 0" />
        <parent link="arm0_shoulder_roll" />
        <child link="arm0_elbow_pitch" />
        <limit effort="1000" lower="0" upper="3.14159265358979311599" velocity="1000.00" />
    </joint>
    <link name="arm0_elbow_roll">
        <visual>
            <origin rpy="0 0 0" xyz="0 0 0" />
            <geometry>
                <mesh filename="package://spot_description/meshes/arm/arm0.link_el1.obj" />
            </geometry>
            <material name="arm0.link_el1">
                <color rgba="0.2 0.2 0.2 1" />
            </material>
        </visual>
        <collision>
            <origin rpy="0 0 0" xyz="0 0 0" />
            <geometry>
                <mesh filename="package://spot_description/meshes/arm/arm0.link_el1.obj" />
            </geometry>
            <material name="arm0.link_el1">
                <color rgba="1 0.2 0.2 1" />
            </material>
        </collision>
        <inertial>
            <mass value="0.1" />
            <origin xyz="0 0 0" rpy="0 0 0" />
            <inertia ixx="0.03" iyy="0.03" izz="0.03" ixy="0.0" ixz="0.0" iyz="0.0" />
        </inertial>
    </link>
    <joint name="arm0_elbow_roll" type="revolute">
        <origin rpy="0 0 0" xyz="0.40330 0.0 0.0750" />
        <axis xyz="1 0 0" />
        <parent link="arm0_elbow_pitch" />
        <child link="arm0_elbow_roll" />
        <limit effort="1000" lower="-2.79252680319092716487" upper="2.79252680319092716487" velocity="1000.00" />
    </joint>
    <link name="arm0_wrist_pitch">
        <visual>
            <origin rpy="0 0 0" xyz="0 0 0" />
            <geometry>
                <mesh filename="package://spot_description/meshes/arm/arm0.link_wr0.obj" />
            </geometry>
            <material name="arm0.link_wr0">
                <color rgba="0.2 0.2 0.2 1" />
            </material>
        </visual>
        <collision>
            <origin rpy="0 0 0" xyz="0 0 0" />
            <geometry>
                <mesh filename="package://spot_description/meshes/arm/arm0.link_wr0.obj" />
            </geometry>
            <material name="arm0.link_wr0">
                <color rgba="1 0.2 0.2 1" />
            </material>
        </collision>
        <inertial>
            <mass value="0.1" />
            <origin xyz="0 0 0" rpy="0 0 0" />
            <inertia ixx="0.03" iyy="0.03" izz="0.03" ixy="0.0" ixz="0.0" iyz="0.0" />
        </inertial>
    </link>
    <joint name="arm0_wrist_pitch" type="revolute">
        <origin rpy="0 0 0" xyz="0.0 0.0 0.0" />
        <axis xyz="0 1 0" />
        <parent link="arm0_elbow_roll" />
        <child link="arm0_wrist_pitch" />
        <limit effort="1000" lower="-1.83259571459404613236" upper="1.83259571459404613236" velocity="1000.00" />
    </joint>
    <link name="arm0_wrist_roll">
        <visual>
            <origin rpy="0 0 0" xyz="0 0 0" />
            <geometry>
                <mesh filename="package://spot_description/meshes/arm/arm0.link_wr1.obj" />
            </geometry>
            <material name="arm0.link_wr1">
                <color rgba="0.2 0.2 0.2 1" />
            </material>
        </visual>
        <collision>
            <origin rpy="0 0 0" xyz="0 0 0" />
            <geometry>
                <mesh filename="package://spot_description/meshes/arm/arm0.link_wr1.obj" />
            </geometry>
            <material name="arm0.link_wr1">
                <color rgba="1 0.2 0.2 1" />
            </material>
        </collision>
        <inertial>
            <mass value="0.1" />
            <origin xyz="0 0 0" rpy="0 0 0" />
            <inertia ixx="0.03" iyy="0.03" izz="0.03" ixy="0.0" ixz="0.0" iyz="0.0" />
        </inertial>
    </link>
    <joint name="arm0_wrist_roll" type="revolute">
        <origin rpy="0 0 0" xyz="0.0 0.0 0.0" />
        <axis xyz="1 0 0" />
        <parent link="arm0_wrist_pitch" />
        <child link="arm0_wrist_roll" />
        <limit effort="1000" lower="-2.87979326579064354163" upper="2.87979326579064354163" velocity="1000.00" />
    </joint>
    <link name="arm0_fingers">
        <visual>
            <origin rpy="0 0 0" xyz="0 0 0" />
            <geometry>
                <mesh filename="package://spot_description/meshes/arm/arm0.link_fngr.obj" />
            </geometry>
            <material name="arm0.link_fngr">
                <color rgba="0.2 0.2 0.2 1" />
            </material>
        </visual>
        <collision>
            <origin rpy="0 0 0" xyz="0 0 0" />
            <geometry>
                <mesh filename="package://spot_description/meshes/arm/arm0.link_fngr.obj" />
            </geometry>
            <material name="arm0.link_fngr">
                <color rgba="0.2 0.2 0.2 1" />
            </material>
        </collision>
        <inertial>
            <mass value="0.1" />
            <origin xyz="0 0 0" rpy="0 0 0" />
            <inertia ixx="0.03" iyy="0.03" izz="0.03" ixy="0.0" ixz="0.0" iyz="0.0" />
        </inertial>
    </link>
    <joint name="arm0_fingers" type="revolute">
        <origin rpy="0 0 0" xyz="0.11745 0 0.014820" />
        <axis xyz="0.0 1.0 0.0" />
        <parent link="arm0_wrist_roll" />
        <child link="arm0_fingers" />
        <limit effort="1000" lower="-1.57" upper="0.0" velocity="1000.00" />
    </joint>
    <joint name="arm0_mount" type="fixed">
        <origin rpy="0 0 0" xyz="0.292 0 0.188" />
        <parent link="base_link" />
        <child link="arm0_base_link" />
    </joint>
    <!-- This file is a placeholder which is included by default from
       spot.urdf.xacro. If a robot is being customized and requires
       additional URDF, set the SPOT_URDF_EXTRAS environment variable
       to the full path of the file you would like included. -->
    <transmission name="trans_front_left_hip_x">
        <type>transmission_interface/SimpleTransmission</type>
        <joint name="front_left_hip_x">
            <hardwareInterface>hardware_interface/EffortJointInterface</hardwareInterface>
        </joint>
        <actuator name="front_left_hip_x_motor">
            <hardwareInterface>hardware_interface/EffortJointInterface</hardwareInterface>
            <mechanicalReduction>1</mechanicalReduction>
        </actuator>
    </transmission>
    <transmission name="trans_front_left_hip_y">
        <type>transmission_interface/SimpleTransmission</type>
        <joint name="front_left_hip_y">
            <hardwareInterface>hardware_interface/EffortJointInterface</hardwareInterface>
        </joint>
        <actuator name="front_left_hip_y_motor">
            <hardwareInterface>hardware_interface/EffortJointInterface</hardwareInterface>
            <mechanicalReduction>1</mechanicalReduction>
        </actuator>
    </transmission>
    <transmission name="trans_front_left_knee">
        <type>transmission_interface/SimpleTransmission</type>
        <joint name="front_left_knee">
            <hardwareInterface>hardware_interface/EffortJointInterface</hardwareInterface>
        </joint>
        <actuator name="front_left_knee_motor">
            <hardwareInterface>hardware_interface/EffortJointInterface</hardwareInterface>
            <mechanicalReduction>1</mechanicalReduction>
        </actuator>
    </transmission>
    <transmission name="trans_front_right_hip_x">
        <type>transmission_interface/SimpleTransmission</type>
        <joint name="front_right_hip_x">
            <hardwareInterface>hardware_interface/EffortJointInterface</hardwareInterface>
        </joint>
        <actuator name="front_right_hip_x_motor">
            <hardwareInterface>hardware_interface/EffortJointInterface</hardwareInterface>
            <mechanicalReduction>1</mechanicalReduction>
        </actuator>
    </transmission>
    <transmission name="trans_front_right_hip_y">
        <type>transmission_interface/SimpleTransmission</type>
        <joint name="front_right_hip_y">
            <hardwareInterface>hardware_interface/EffortJointInterface</hardwareInterface>
        </joint>
        <actuator name="front_right_hip_y_motor">
            <hardwareInterface>hardware_interface/EffortJointInterface</hardwareInterface>
            <mechanicalReduction>1</mechanicalReduction>
        </actuator>
    </transmission>
    <transmission name="trans_front_right_knee">
        <type>transmission_interface/SimpleTransmission</type>
        <joint name="front_right_knee">
            <hardwareInterface>hardware_interface/EffortJointInterface</hardwareInterface>
        </joint>
        <actuator name="front_right_knee_motor">
            <hardwareInterface>hardware_interface/EffortJointInterface</hardwareInterface>
            <mechanicalReduction>1</mechanicalReduction>
        </actuator>
    </transmission>
    <transmission name="trans_rear_left_hip_x">
        <type>transmission_interface/SimpleTransmission</type>
        <joint name="rear_left_hip_x">
            <hardwareInterface>hardware_interface/EffortJointInterface</hardwareInterface>
        </joint>
        <actuator name="rear_left_hip_x_motor">
            <hardwareInterface>hardware_interface/EffortJointInterface</hardwareInterface>
            <mechanicalReduction>1</mechanicalReduction>
        </actuator>
    </transmission>
    <transmission name="trans_rear_left_hip_y">
        <type>transmission_interface/SimpleTransmission</type>
        <joint name="rear_left_hip_y">
            <hardwareInterface>hardware_interface/EffortJointInterface</hardwareInterface>
        </joint>
        <actuator name="rear_left_hip_y_motor">
            <hardwareInterface>hardware_interface/EffortJointInterface</hardwareInterface>
            <mechanicalReduction>1</mechanicalReduction>
        </actuator>
    </transmission>
    <transmission name="trans_rear_left_knee">
        <type>transmission_interface/SimpleTransmission</type>
        <joint name="rear_left_knee">
            <hardwareInterface>hardware_interface/EffortJointInterface</hardwareInterface>
        </joint>
        <actuator name="rear_left_knee_motor">
            <hardwareInterface>hardware_interface/EffortJointInterface</hardwareInterface>
            <mechanicalReduction>1</mechanicalReduction>
        </actuator>
    </transmission>
    <transmission name="trans_rear_right_hip_x">
        <type>transmission_interface/SimpleTransmission</type>
        <joint name="rear_right_hip_x">
            <hardwareInterface>hardware_interface/EffortJointInterface</hardwareInterface>
        </joint>
        <actuator name="rear_right_hip_x_motor">
            <hardwareInterface>hardware_interface/EffortJointInterface</hardwareInterface>
            <mechanicalReduction>1</mechanicalReduction>
        </actuator>
    </transmission>
    <transmission name="trans_rear_right_hip_y">
        <type>transmission_interface/SimpleTransmission</type>
        <joint name="rear_right_hip_y">
            <hardwareInterface>hardware_interface/EffortJointInterface</hardwareInterface>
        </joint>
        <actuator name="rear_right_hip_y_motor">
            <hardwareInterface>hardware_interface/EffortJointInterface</hardwareInterface>
            <mechanicalReduction>1</mechanicalReduction>
        </actuator>
    </transmission>
    <transmission name="trans_rear_right_knee">
        <type>transmission_interface/SimpleTransmission</type>
        <joint name="rear_right_knee">
            <hardwareInterface>hardware_interface/EffortJointInterface</hardwareInterface>
        </joint>
        <actuator name="rear_right_knee_motor">
            <hardwareInterface>hardware_interface/EffortJointInterface</hardwareInterface>
            <mechanicalReduction>1</mechanicalReduction>
        </actuator>
    </transmission>
    <transmission name="trans_arm0_fingers">
        <type>transmission_interface/SimpleTransmission</type>
        <joint name="arm0_fingers">
            <hardwareInterface>hardware_interface/EffortJointInterface</hardwareInterface>
        </joint>
        <actuator name="arm0_fingers_motor">
            <hardwareInterface>hardware_interface/EffortJointInterface</hardwareInterface>
            <mechanicalReduction>1</mechanicalReduction>
        </actuator>
    </transmission>
    <gazebo>
        <plugin name="gazebo_ros_control">
            <robotNamespace>/</robotNamespace>
        </plugin>
    </gazebo>
</robot>

